2020-03-07 17:52:55,720 INFO: Microblog startup [in C:\Users\balre\Desktop\microblog\app\__init__.py:48]
2020-03-07 17:53:01,984 ERROR: Exception on /edit_profile [POST] [in c:\users\balre\appdata\local\programs\python\python37\lib\site-packages\flask\app.py:1891]
Traceback (most recent call last):
  File "c:\users\balre\appdata\local\programs\python\python37\lib\site-packages\sqlalchemy\engine\base.py", line 1246, in _execute_context
    cursor, statement, parameters, context
  File "c:\users\balre\appdata\local\programs\python\python37\lib\site-packages\sqlalchemy\engine\default.py", line 588, in do_execute
    cursor.execute(statement, parameters)
psycopg2.errors.UniqueViolation: duplicate key value violates unique constraint "ix_user_username"
DETAIL:  Key (username)=(test) already exists.


The above exception was the direct cause of the following exception:

Traceback (most recent call last):
  File "c:\users\balre\appdata\local\programs\python\python37\lib\site-packages\flask\app.py", line 2446, in wsgi_app
    response = self.full_dispatch_request()
  File "c:\users\balre\appdata\local\programs\python\python37\lib\site-packages\flask\app.py", line 1951, in full_dispatch_request
    rv = self.handle_user_exception(e)
  File "c:\users\balre\appdata\local\programs\python\python37\lib\site-packages\flask\app.py", line 1820, in handle_user_exception
    reraise(exc_type, exc_value, tb)
  File "c:\users\balre\appdata\local\programs\python\python37\lib\site-packages\flask\_compat.py", line 39, in reraise
    raise value
  File "c:\users\balre\appdata\local\programs\python\python37\lib\site-packages\flask\app.py", line 1949, in full_dispatch_request
    rv = self.dispatch_request()
  File "c:\users\balre\appdata\local\programs\python\python37\lib\site-packages\flask\app.py", line 1935, in dispatch_request
    return self.view_functions[rule.endpoint](**req.view_args)
  File "c:\users\balre\appdata\local\programs\python\python37\lib\site-packages\flask_login\utils.py", line 272, in decorated_view
    return func(*args, **kwargs)
  File "C:\Users\balre\Desktop\microblog\app\routes.py", line 85, in edit_profile
    db.session.commit()
  File "c:\users\balre\appdata\local\programs\python\python37\lib\site-packages\sqlalchemy\orm\scoping.py", line 162, in do
    return getattr(self.registry(), name)(*args, **kwargs)
  File "c:\users\balre\appdata\local\programs\python\python37\lib\site-packages\sqlalchemy\orm\session.py", line 1036, in commit
    self.transaction.commit()
  File "c:\users\balre\appdata\local\programs\python\python37\lib\site-packages\sqlalchemy\orm\session.py", line 503, in commit
    self._prepare_impl()
  File "c:\users\balre\appdata\local\programs\python\python37\lib\site-packages\sqlalchemy\orm\session.py", line 482, in _prepare_impl
    self.session.flush()
  File "c:\users\balre\appdata\local\programs\python\python37\lib\site-packages\sqlalchemy\orm\session.py", line 2479, in flush
    self._flush(objects)
  File "c:\users\balre\appdata\local\programs\python\python37\lib\site-packages\sqlalchemy\orm\session.py", line 2617, in _flush
    transaction.rollback(_capture_exception=True)
  File "c:\users\balre\appdata\local\programs\python\python37\lib\site-packages\sqlalchemy\util\langhelpers.py", line 68, in __exit__
    compat.reraise(exc_type, exc_value, exc_tb)
  File "c:\users\balre\appdata\local\programs\python\python37\lib\site-packages\sqlalchemy\util\compat.py", line 153, in reraise
    raise value
  File "c:\users\balre\appdata\local\programs\python\python37\lib\site-packages\sqlalchemy\orm\session.py", line 2577, in _flush
    flush_context.execute()
  File "c:\users\balre\appdata\local\programs\python\python37\lib\site-packages\sqlalchemy\orm\unitofwork.py", line 422, in execute
    rec.execute(self)
  File "c:\users\balre\appdata\local\programs\python\python37\lib\site-packages\sqlalchemy\orm\unitofwork.py", line 589, in execute
    uow,
  File "c:\users\balre\appdata\local\programs\python\python37\lib\site-packages\sqlalchemy\orm\persistence.py", line 236, in save_obj
    update,
  File "c:\users\balre\appdata\local\programs\python\python37\lib\site-packages\sqlalchemy\orm\persistence.py", line 996, in _emit_update_statements
    statement, multiparams
  File "c:\users\balre\appdata\local\programs\python\python37\lib\site-packages\sqlalchemy\engine\base.py", line 982, in execute
    return meth(self, multiparams, params)
  File "c:\users\balre\appdata\local\programs\python\python37\lib\site-packages\sqlalchemy\sql\elements.py", line 293, in _execute_on_connection
    return connection._execute_clauseelement(self, multiparams, params)
  File "c:\users\balre\appdata\local\programs\python\python37\lib\site-packages\sqlalchemy\engine\base.py", line 1101, in _execute_clauseelement
    distilled_params,
  File "c:\users\balre\appdata\local\programs\python\python37\lib\site-packages\sqlalchemy\engine\base.py", line 1250, in _execute_context
    e, statement, parameters, cursor, context
  File "c:\users\balre\appdata\local\programs\python\python37\lib\site-packages\sqlalchemy\engine\base.py", line 1476, in _handle_dbapi_exception
    util.raise_from_cause(sqlalchemy_exception, exc_info)
  File "c:\users\balre\appdata\local\programs\python\python37\lib\site-packages\sqlalchemy\util\compat.py", line 398, in raise_from_cause
    reraise(type(exception), exception, tb=exc_tb, cause=cause)
  File "c:\users\balre\appdata\local\programs\python\python37\lib\site-packages\sqlalchemy\util\compat.py", line 152, in reraise
    raise value.with_traceback(tb)
  File "c:\users\balre\appdata\local\programs\python\python37\lib\site-packages\sqlalchemy\engine\base.py", line 1246, in _execute_context
    cursor, statement, parameters, context
  File "c:\users\balre\appdata\local\programs\python\python37\lib\site-packages\sqlalchemy\engine\default.py", line 588, in do_execute
    cursor.execute(statement, parameters)
sqlalchemy.exc.IntegrityError: (psycopg2.errors.UniqueViolation) duplicate key value violates unique constraint "ix_user_username"
DETAIL:  Key (username)=(test) already exists.

[SQL: UPDATE "user" SET username=%(username)s, about_me=%(about_me)s WHERE "user".id = %(user_id)s]
[parameters: {'username': 'test', 'about_me': 'v sbvgvgweewg', 'user_id': 6}]
(Background on this error at: http://sqlalche.me/e/gkpj)
2020-03-07 18:01:53,362 INFO: Microblog startup [in C:\Users\balre\Desktop\microblog\app\__init__.py:48]
2020-03-07 20:00:37,672 INFO: Microblog startup [in C:\Users\balre\Desktop\microblog\app\__init__.py:48]
2020-03-07 20:02:30,893 INFO: Microblog startup [in C:\Users\balre\Desktop\microblog\app\__init__.py:48]
2020-03-07 20:03:22,467 INFO: Microblog startup [in C:\Users\balre\Desktop\microblog\app\__init__.py:48]
2020-03-07 20:45:55,673 INFO: Microblog startup [in C:\Users\balre\Desktop\microblog\app\__init__.py:48]
